Workbook
Name Slicer_Column1: #N/A
Name Slicer_Quarter: #N/A
Name Slicer_Day: #N/A

Sheet Dashboard
B1: Non-Profit Operations Dashboard 2026
B4: Mock data dashboard tracking service delivery, income, donations, WEV outcomes, marketing activity, and volunteer support. Mock Data Portfolio Project inspired by Dress for Success operational reporting.
B6: Total Income | E6: Completion Rate | H6: Completed Styling | K6: WEV Employed | N6: Donations Received(Kg) | Q6: Re-Donations (Kg) | T6: Volunteer Count | W6: Volunteer Hours
B8: =GETPIVOTDATA("Sum of Total Income",'Pivot table'!$A$3) -> 68713.69 | E8: =GETPIVOTDATA("Sum of Completion Rate",'Pivot table'!$A$3) -> 0.86440678 | H8: =GETPIVOTDATA("Sum of Total Completed Styling Services",'Pivot table'!$A$3) -> 765 | K8: =GETPIVOTDATA("Sum of WEV Employed",'Pivot table'!$A$3) -> 33 | N8: =GETPIVOTDATA("Sum of Donations Received kg",'Pivot table'!$A$3) -> 7603.5 | Q8: =GETPIVOTDATA("Sum of Re-Donations kg",'Pivot table'!$A$3) -> 1138.6 | T8: =GETPIVOTDATA("Sum of Volunteer Count Total",'Pivot table'!$A$3) -> 2856 | W8: =GETPIVOTDATA("Sum of Volunteer Hours Total",'Pivot table'!$A$3) -> 10665.5

Sheet Pivot table
A3: Sum of Total Stylings Registrations | B3: Sum of Total Completed Styling Services | C3: Sum of Completion Rate | D3: Sum of Volunteer Count Total | E3: Sum of Volunteer Hours Total | F3: Sum of Total Income | G3: Sum of Donations Received kg | H3: Sum of Re-Donations kg | I3: Sum of WEV Employed
A4: 885 | B4: 765 | C4: 0.86440678 | D4: 2856 | E4: 10665.5 | F4: 68713.69 | G4: 7603.5 | H4: 1138.6 | I4: 33
A6: Month | B6: Sum of Total Income
A7: January | B7: 6313.46
A8: February | B8: 5695.08
A9: March | B9: 4999.83
A10: April | B10: 4884
A11: May | B11: 5384.65
A12: June | B12: 6499
A13: July | B13: 5647.43
A14: August | B14: 5173.04
A15: September | B15: 7142.4
A16: October | B16: 6152.84
A17: November | B17: 5321.49
A18: December | B18: 5500.47
A19: Grand Total | B19: 68713.69
A21: Month | B21: Sum of Interview Styling Completed | C21: Sum of Confidence Styling Completed
A22: January | B22: 39 | C22: 27
A23: February | B23: 32 | C23: 24
A24: March | B24: 42 | C24: 34
A25: April | B25: 45 | C25: 21
A26: May | B26: 29 | C26: 30
A27: June | B27: 35 | C27: 27
A28: July | B28: 39 | C28: 26
A29: August | B29: 44 | C29: 33
A30: September | B30: 39 | C30: 26
A31: October | B31: 44 | C31: 23
A32: November | B32: 29 | C32: 22
A33: December | B33: 25 | C33: 30
A34: Grand Total | B34: 442 | C34: 323
A36: Sum of Total Male | B36: Sum of Total Female | C36: Sum of Total Non-Binary | E36: Gender | F36: Total
A37: 198 | B37: 559 | C37: 8 | E37: Male | F37: =GETPIVOTDATA("Sum of Total Male",$A$36) -> 198
E38: Female | F38: =GETPIVOTDATA("Sum of Total Female",$A$36) -> 559
E39: Non-Binary | F39: =GETPIVOTDATA("Sum of Total Non-Binary",$A$36) -> 8
A42: Sum of WEV Registrations | B42: Sum of WEV Onboarded | C42: Sum of WEV Offboarded | D42: Sum of WEV Employed | F42: WEV Stage | G42: Total
A43: 171 | B43: 70 | C43: 71 | D43: 33 | F43: Registrations | G43: =GETPIVOTDATA("Sum of WEV Registrations",$A$42) -> 171
F44: Onboarded | G44: =GETPIVOTDATA("Sum of WEV Onboarded",$A$42) -> 70
F45: Offboarded | G45: =GETPIVOTDATA("Sum of WEV Offboarded",$A$42) -> 71
F46: Employed | G46: =GETPIVOTDATA("Sum of WEV Employed",$A$42) -> 33
A48: Month | B48: Sum of Donations Received kg | C48: Sum of Re-Donations kg
...

Sheet Raw_Data
A1: Month | B1: Quarter | C1: Week | D1: Date | E1: Day | F1: Interview Styling Registrations | G1: Interview Styling Completed | H1: Interview Styling Male | I1: Interview Styling Female | J1: Interview Styling Non-Binary | K1: Confidence Styling Registrations | L1: Confidence Styling Completed | M1: Confidence Styling Male | N1: Confidence Styling Female | O1: Confidence Styling Non-Binary | P1: WEV Registrations | Q1: WEV Onboarded | R1: WEV Offboarded | S1: WEV Employed | T1: Donations Received kg | U1: Re-Donations kg | V1: Customers Purchased | W1: Total Income | X1: Social Media Outreach | Y1: Social Media Engagement | Z1: Volunteer Count Retail | AA1: Volunteer Count HR | AB1: Volunteer Count Business Support | AC1: Volunteer Count Marketing | AD1: Volunteer Count Stylist | AE1: Volunteer Count Clothing Management | AF1: Volunteer Count Total | AG1: Volunteer Hours Retail | AH1: Volunteer Hours HR | AI1: Volunteer Hours Business Support | AJ1: Volunteer Hours Marketing | AK1: Volunteer Hours Stylist | AL1: Volunteer Hours Clothing Management | AM1: Volunteer Hours Total | AN1: Total Stylings Registrations | AO1: Total Completed Styling Services | AP1: Total Male | AQ1: Total Female | AR1: Total Non-Binary
A2: January | B2: Q1 | C2: Week 1 | D2: 46023 | E2: =TEXT(D2,"dddd") -> Thursday | F2: 3 | G2: 3 | H2: 0 | I2: 3 | J2: 0 | K2: 1 | L2: 0 | M2: 0 | N2: 0 | O2: 0 | P2: 1 | Q2: 0 | R2: 0 | S2: 0 | T2: 0 | U2: 0 | V2: 3 | W2: 85.25 | X2: 1636 | Y2: 153 | Z2: 2 | AA2: 2 | AB2: 2 | AC2: 0 | AD2: 4 | AE2: 1 | AF2: 11 | AG2: 9 | AH2: 7.5 | AI2: 9 | AJ2: 0 | AK2: 18.5 | AL2: 4 | AM2: 48 | AN2: =tbl_operations[[#This Row],[Interview Styling Registrations]]+tbl_operations[[#This Row],[Confidence Styling Registrations]] -> 4 | AO2: =tbl_operations[[#This Row],[Interview Styling Completed]]+tbl_operations[[#This Row],[Confidence Styling Completed]] -> 3 | AP2: =tbl_operations[[#This Row],[Interview Styling Male]]+tbl_operations[[#This Row],[Confidence Styling Male]] -> 0 | AQ2: =tbl_operations[[#This Row],[Interview Styling Female]]+tbl_operations[[#This Row],[Confidence Styling Female]] -> 3 | AR2: =tbl_operations[[#This Row],[Interview Styling Non-Binary]]+tbl_operations[[#This Row],[Confidence Styling Non-Binary]] -> 0
A3: January | B3: Q1 | C3: Week 1 | D3: 46024 | E3: =TEXT(D3,"dddd") -> Friday | F3: 3 | G3: 3 | H3: 1 | I3: 2 | J3: 0 | K3: 0 | L3: 0 | M3: 0 | N3: 0 | O3: 0 | P3: 1 | Q3: 1 | R3: 0 | S3: 0 | T3: 55.6 | U3: 0 | V3: 17 | W3: 443.68 | X3: 811 | Y3: 85 | Z3: 3 | AA3: 1 | AB3: 0 | AC3: 0 | AD3: 1 | AE3: 3 | AF3: 8 | AG3: 13 | AH3: 4 | AI3: 0 | AJ3: 0 | AK3: 5.5 | AL3: 7.5 | AM3: 30 | AN3: =tbl_operations[[#This Row],[Interview Styling Registrations]]+tbl_operations[[#This Row],[Confidence Styling Registrations]] -> 3 | AO3: =tbl_operations[[#This Row],[Interview Styling Completed]]+tbl_operations[[#This Row],[Confidence Styling Completed]] -> 3 | AP3: =tbl_operations[[#This Row],[Interview Styling Male]]+tbl_operations[[#This Row],[Confidence Styling Male]] -> 1 | AQ3: =tbl_operations[[#This Row],[Interview Styling Female]]+tbl_operations[[#This Row],[Confidence Styling Female]] -> 2 | AR3: =tbl_operations[[#This Row],[Interview Styling Non-Binary]]+tbl_operations[[#This Row],[Confidence Styling Non-Binary]] -> 0
A4: January | B4: Q1 | C4: Week 2 | D4: 46027 | E4: =TEXT(D4,"dddd") -> Monday | F4: 1 | G4: 1 | H4: 1 | I4: 0 | J4: 0 | K4: 2 | L4: 2 | M4: 1 | N4: 1 | O4: 0 | P4: 1 | Q4: 0 | R4: 0 | S4: 0 | T4: 0 | U4: 7.2 | V4: 8 | W4: 211.98 | X4: 295 | Y4: 18 | Z4: 4 | AA4: 1 | AB4: 0 | AC4: 0 | AD4: 4 | AE4: 2 | AF4: 11 | AG4: 12.5 | AH4: 2.5 | AI4: 0 | AJ4: 0 | AK4: 10.5 | AL4: 9 | AM4: 34.5 | AN4: =tbl_operations[[#This Row],[Interview Styling Registrations]]+tbl_operations[[#This Row],[Confidence Styling Registrations]] -> 3 | AO4: =tbl_operations[[#This Row],[Interview Styling Completed]]+tbl_operations[[#This Row],[Confidence Styling Completed]] -> 3 | AP4: =tbl_operations[[#This Row],[Interview Styling Male]]+tbl_operations[[#This Row],[Confidence Styling Male]] -> 2 | AQ4: =tbl_operations[[#This Row],[Interview Styling Female]]+tbl_operations[[#This Row],[Confidence Styling Female]] -> 1 | AR4: =tbl_operations[[#This Row],[Interview Styling Non-Binary]]+tbl_operations[[#This Row],[Confidence Styling Non-Binary]] -> 0
A5: January | B5: Q1 | C5: Week 2 | D5: 46028 | E5: =TEXT(D5,"dddd") -> Tuesday | F5: 1 | G5: 0 | H5: 0 | I5: 0 | J5: 0 | K5: 2 | L5: 2 | M5: 1 | N5: 1 | O5: 0 | P5: 1 | Q5: 0 | R5: 1 | S5: 0 | T5: 38.9 | U5: 4.9 | V5: 16 | W5: 194.65 | X5: 726 | Y5: 69 | Z5: 1 | AA5: 1 | AB5: 1 | AC5: 0 | AD5: 4 | AE5: 3 | AF5: 10 | AG5: 5.5 | AH5: 3.5 | AI5: 4 | AJ5: 0 | AK5: 10.5 | AL5: 10.5 | AM5: 34 | AN5: =tbl_operations[[#This Row],[Interview Styling Registrations]]+tbl_operations[[#This Row],[Confidence Styling Registrations]] -> 3 | AO5: =tbl_operations[[#This Row],[Interview Styling Completed]]+tbl_operations[[#This Row],[Confidence Styling Completed]] -> 2 | AP5: =tbl_operations[[#This Row],[Interview Styling Male]]+tbl_operations[[#This Row],[Confidence Styling Male]] -> 1 | AQ5: =tbl_operations[[#This Row],[Interview Styling Female]]+tbl_operations[[#This Row],[Confidence Styling Female]] -> 1 | AR5: =tbl_operations[[#This Row],[Interview Styling Non-Binary]]+tbl_operations[[#This Row],[Confidence Styling Non-Binary]] -> 0
A6: January | B6: Q1 | C6: Week 2 | D6: 46029 | E6: =TEXT(D6,"dddd") -> Wednesday | F6: 4 | G6: 3 | H6: 0 | I6: 3 | J6: 0 | K6: 0 | L6: 0 | M6: 0 | N6: 0 | O6: 0 | P6: 0 | Q6: 0 | R6: 0 | S6: 0 | T6: 20.9 | U6: 5.6 | V6: 9 | W6: 256.81 | X6: 1368 | Y6: 72 | Z6: 4 | AA6: 0 | AB6: 2 | AC6: 1 | AD6: 2 | AE6: 3 | AF6: 12 | AG6: 9 | AH6: 0 | AI6: 7.5 | AJ6: 2.5 | AK6: 4.5 | AL6: 8.5 | AM6: 32 | AN6: =tbl_operations[[#This Row],[Interview Styling Registrations]]+tbl_operations[[#This Row],[Confidence Styling Registrations]] -> 4 | AO6: =tbl_operations[[#This Row],[Interview Styling Completed]]+tbl_operations[[#This Row],[Confidence Styling Completed]] -> 3 | AP6: =tbl_operations[[#This Row],[Interview Styling Male]]+tbl_operations[[#This Row],[Confidence Styling Male]] -> 0 | AQ6: =tbl_operations[[#This Row],[Interview Styling Female]]+tbl_operations[[#This Row],[Confidence Styling Female]] -> 3 | AR6: =tbl_operations[[#This Row],[Interview Styling Non-Binary]]+tbl_operations[[#This Row],[Confidence Styling Non-Binary]] -> 0
A7: January | B7: Q1 | C7: Week 2 | D7: 46030 | E7: =TEXT(D7,"dddd") -> Thursday | F7: 1 | G7: 1 | H7: 1 | I7: 0 | J7: 0 | K7: 3 | L7: 2 | M7: 1 | N7: 1 | O7: 0 | P7: 0 | Q7: 1 | R7: 1 | S7: 0 | T7: 27.7 | U7: 6.7 | V7: 16 | W7: 320.91 | X7: 1839 | Y7: 232 | Z7: 1 | AA7: 1 | AB7: 0 | AC7: 0 | AD7: 1 | AE7: 4 | AF7: 7 | AG7: 4 | AH7: 4.5 | AI7: 0 | AJ7: 0 | AK7: 3.5 | AL7: 11.5 | AM7: 23.5 | AN7: =tbl_operations[[#This Row],[Interview Styling Registrations]]+tbl_operations[[#This Row],[Confidence Styling Registrations]] -> 4 | AO7: =tbl_operations[[#This Row],[Interview Styling Completed]]+tbl_operations[[#This Row],[Confidence Styling Completed]] -> 3 | AP7: =tbl_operations[[#This Row],[Interview Styling Male]]+tbl_operations[[#This Row],[Confidence Styling Male]] -> 2 | AQ7: =tbl_operations[[#This Row],[Interview Styling Female]]+tbl_operations[[#This Row],[Confidence Styling Female]] -> 1 | AR7: =tbl_operations[[#This Row],[Interview Styling Non-Binary]]+tbl_operations[[#This Row],[Confidence Styling Non-Binary]] -> 0
A8: January | B8: Q1 | C8: Week 2 | D8: 46031 | E8: =TEXT(D8,"dddd") -> Friday | F8: 0 | G8: 0 | H8: 0 | I8: 0 | J8: 0 | K8: 3 | L8: 2 | M8: 1 | N8: 1 | O8: 0 | P8: 0 | Q8: 0 | R8: 1 | S8: 0 | T8: 63.3 | U8: 16.1 | V8: 16 | W8: 200.85 | X8: 1285 | Y8: 142 | Z8: 3 | AA8: 0 | AB8: 2 | AC8: 1 | AD8: 2 | AE8: 2 | AF8: 10 | AG8: 10.5 | AH8: 0 | AI8: 9 | AJ8: 3 | AK8: 10.5 | AL8: 10.5 | AM8: 43.5 | AN8: =tbl_operations[[#This Row],[Interview Styling Registrations]]+tbl_operations[[#This Row],[Confidence Styling Registrations]] -> 3 | AO8: =tbl_operations[[#This Row],[Interview Styling Completed]]+tbl_operations[[#This Row],[Confidence Styling Completed]] -> 2 | AP8: =tbl_operations[[#This Row],[Interview Styling Male]]+tbl_operations[[#This Row],[Confidence Styling Male]] -> 1 | AQ8: =tbl_operations[[#This Row],[Interview Styling Female]]+tbl_operations[[#This Row],[Confidence Styling Female]] -> 1 | AR8: =tbl_operations[[#This Row],[Interview Styling Non-Binary]]+tbl_operations[[#This Row],[Confidence Styling Non-Binary]] -> 0
A9: January | B9: Q1 | C9: Week 3 | D9: 46034 | E9: =TEXT(D9,"dddd") -> Monday | F9: 2 | G9: 2 | H9: 0 | I9: 2 | J9: 0 | K9: 2 | L9: 2 | M9: 0 | N9: 2 | O9: 0 | P9: 1 | Q9: 0 | R9: 1 | S9: 0 | T9: 25.5 | U9: 8.1 | V9: 11 | W9: 141.98 | X9: 970 | Y9: 52 | Z9: 4 | AA9: 1 | AB9: 0 | AC9: 1 | AD9: 3 | AE9: 3 | AF9: 12 | AG9: 20.5 | AH9: 2.5 | AI9: 0 | AJ9: 3.5 | AK9: 15.5 | AL9: 14.5 | AM9: 56.5 | AN9: =tbl_operations[[#This Row],[Interview Styling Registrations]]+tbl_operations[[#This Row],[Confidence Styling Registrations]] -> 4 | AO9: =tbl_operations[[#This Row],[Interview Styling Completed]]+tbl_operations[[#This Row],[Confidence Styling Completed]] -> 4 | AP9: =tbl_operations[[#This Row],[Interview Styling Male]]+tbl_operations[[#This Row],[Confidence Styling Male]] -> 0 | AQ9: =tbl_operations[[#This Row],[Interview Styling Female]]+tbl_operations[[#This Row],[Confidence Styling Female]] -> 4 | AR9: =tbl_operations[[#This Row],[Interview Styling Non-Binary]]+tbl_operations[[#This Row],[Confidence Styling Non-Binary]] -> 0
A10: January | B10: Q1 | C10: Week 3 | D10: 46035 | E10: =TEXT(D10,"dddd") -> Tuesday | F10: 3 | G10: 3 | H10: 1 | I10: 2 | J10: 0 | K10: 0 | L10: 0 | M10: 0 | N10: 0 | O10: 0 | P10: 0 | Q10: 0 | R10: 0 | S10: 1 | T10: 59.4 | U10: 7.7 | V10: 11 | W10: 275.98 | X10: 1484 | Y10: 151 | Z10: 2 | AA10: 0 | AB10: 2 | AC10: 1 | AD10: 5 | AE10: 2 | AF10: 12 | AG10: 6.5 | AH10: 0 | AI10: 9 | AJ10: 4 | AK10: 17 | AL10: 8.5 | AM10: 45 | AN10: =tbl_operations[[#This Row],[Interview Styling Registrations]]+tbl_operations[[#This Row],[Confidence Styling Registrations]] -> 3 | AO10: =tbl_operations[[#This Row],[Interview Styling Completed]]+tbl_operations[[#This Row],[Confidence Styling Completed]] -> 3 | AP10: =tbl_operations[[#This Row],[Interview Styling Male]]+tbl_operations[[#This Row],[Confidence Styling Male]] -> 1 | AQ10: =tbl_operations[[#This Row],[Interview Styling Female]]+tbl_operations[[#This Row],[Confidence Styling Female]] -> 2 | AR10: =tbl_operations[[#This Row],[Interview Styling Non-Binary]]+tbl_operations[[#This Row],[Confidence Styling Non-Binary]] -> 0
A11: January | B11: Q1 | C11: Week 3 | D11: 46036 | E11: =TEXT(D11,"dddd") -> Wednesday | F11: 1 | G11: 1 | H11: 0 | I11: 1 | J11: 0 | K11: 1 | L11: 1 | M11: 0 | N11: 1 | O11: 0 | P11: 0 | Q11: 1 | R11: 1 | S11: 0 | T11: 0 | U11: 0 | V11: 17 | W11: 459.37 | X11: 793 | Y11: 85 | Z11: 2 | AA11: 2 | AB11: 1 | AC11: 2 | AD11: 4 | AE11: 2 | AF11: 13 | AG11: 7.5 | AH11: 7.5 | AI11: 5.5 | AJ11: 6.5 | AK11: 11.5 | AL11: 5.5 | AM11: 44 | AN11: =tbl_operations[[#This Row],[Interview Styling Registrations]]+tbl_operations[[#This Row],[Confidence Styling Registrations]] -> 2 | AO11: =tbl_operations[[#This Row],[Interview Styling Completed]]+tbl_operations[[#This Row],[Confidence Styling Completed]] -> 2 | AP11: =tbl_operations[[#This Row],[Interview Styling Male]]+tbl_operations[[#This Row],[Confidence Styling Male]] -> 0 | AQ11: =tbl_operations[[#This Row],[Interview Styling Female]]+tbl_operations[[#This Row],[Confidence Styling Female]] -> 2 | AR11: =tbl_operations[[#This Row],[Interview Styling Non-Binary]]+tbl_operations[[#This Row],[Confidence Styling Non-Binary]] -> 0
A12: January | B12: Q1 | C12: Week 3 | D12: 46037 | E12: =TEXT(D12,"dddd") -> Thursday | F12: 2 | G12: 2 | H12: 0 | I12: 2 | J12: 0 | K12: 3 | L12: 2 | M12: 0 | N12: 2 | O12: 0 | P12: 2 | Q12: 0 | R12: 0 | S12: 0 | T12: 0 | U12: 8.2 | V12: 3 | W12: 65.75 | X12: 736 | Y12: 15 | Z12: 4 | AA12: 0 | AB12: 1 | AC12: 1 | AD12: 3 | AE12: 4 | AF12: 13 | AG12: 13 | AH12: 0 | AI12: 3 | AJ12: 4.5 | AK12: 13 | AL12: 21.5 | AM12: 55 | AN12: =tbl_operations[[#This Row],[Interview Styling Registrations]]+tbl_operations[[#This Row],[Confidence Styling Registrations]] -> 5 | AO12: =tbl_operations[[#This Row],[Interview Styling Completed]]+tbl_operations[[#This Row],[Confidence Styling Completed]] -> 4 | AP12: =tbl_operations[[#This Row],[Interview Styling Male]]+tbl_operations[[#This Row],[Confidence Styling Male]] -> 0 | AQ12: =tbl_operations[[#This Row],[Interview Styling Female]]+tbl_operations[[#This Row],[Confidence Styling Female]] -> 4 | AR12: =tbl_operations[[#This Row],[Interview Styling Non-Binary]]+tbl_operations[[#This Row],[Confidence Styling Non-Binary]] -> 0
A13: January | B13: Q1 | C13: Week 3 | D13: 46038 | E13: =TEXT(D13,"dddd") -> Friday | F13: 4 | G13: 4 | H13: 1 | I13: 3 | J13: 0 | K13: 1 | L13: 0 | M13: 0 | N13: 0 | O13: 0 | P13: 1 | Q13: 1 | R13: 0 | S13: 0 | T13: 0 | U13: 17.3 | V13: 15 | W13: 435.96 | X13: 1100 | Y13: 169 | Z13: 4 | AA13: 1 | AB13: 2 | AC13: 0 | AD13: 5 | AE13: 4 | AF13: 16 | AG13: 9 | AH13: 3.5 | AI13: 6.5 | AJ13: 0 | AK13: 23 | AL13: 17 | AM13: 59 | AN13: =tbl_operations[[#This Row],[Interview Styling Registrations]]+tbl_operations[[#This Row],[Confidence Styling Registrations]] -> 5 | AO13: =tbl_operations[[#This Row],[Interview Styling Completed]]+tbl_operations[[#This Row],[Confidence Styling Completed]] -> 4 | AP13: =tbl_operations[[#This Row],[Interview Styling Male]]+tbl_operations[[#This Row],[Confidence Styling Male]] -> 1 | AQ13: =tbl_operations[[#This Row],[Interview Styling Female]]+tbl_operations[[#This Row],[Confidence Styling Female]] -> 3 | AR13: =tbl_operations[[#This Row],[Interview Styling Non-Binary]]+tbl_operations[[#This Row],[Confidence Styling Non-Binary]] -> 0
... A262: December | B262: Q4 | C262: Week 5 | D262: 46387 | E262: =TEXT(D262,"dddd") -> Thursday | F262: 3 | G262: 2 | H262: 0 | I262: 2 | J262: 0 | K262: 2 | L262: 2 | M262: 0 | N262: 2 | O262: 0 | P262: 0 | Q262: 1 | R262: 0 | S262: 1 | T262: 12.9 | U262: 0 | V262: 14 | W262: 309.64 | X262: 1880 | Y262: 117 | Z262: 2 | AA262: 0 | AB262: 0 | AC262: 1 | AD262: 3 | AE262: 2 | AF262: 8 | AG262: 4.5 | AH262: 0 | AI262: 0 | AJ262: 5.5 | AK262: 10.5 | AL262: 7 | AM262: 27.5 | AN262: =tbl_operations[[#This Row],[Interview Styling Registrations]]+tbl_operations[[#This Row],[Confidence Styling Registrations]] -> 5 | AO262: =tbl_operations[[#This Row],[Interview Styling Completed]]+tbl_operations[[#This Row],[Confidence Styling Completed]] -> 4 | AP262: =tbl_operations[[#This Row],[Interview Styling Male]]+tbl_operations[[#This Row],[Confidence Styling Male]] -> 0 | AQ262: =tbl_operations[[#This Row],[Interview Styling Female]]+tbl_operations[[#This Row],[Confidence Styling Female]] -> 4 | AR262: =tbl_operations[[#This Row],[Interview Styling Non-Binary]]+tbl_operations[[#This Row],[Confidence Styling Non-Binary]] -> 0

Sheet Monthly Report
E1: MONTHLY OPERATIONS REPORT - YFS - WELLINGTON HUB
C4: Interview Styling | H4: Confidence Styling | M4: WEV Program | Q4: Donations(kg) | S4: Terrace Income | U4: Marketing | W4: Volunteer Count by category | AD4: Volunteer Hours by category
B5: MONTH | C5: Registrations | D5: Completed | E5: Male | F5: Female | G5: Non-Binary | H5: Registrations | I5: Completed | J5: Male | K5: Female | L5: Non-Binary | M5: Registrations | N5: Onboarded | O5: Offboarded | P5: Employed | Q5: Donations Received | R5: Re-Donations | S5: Customers Purchased | T5: Total Income | U5: Social Media Outreach | V5: Social Media Engagement | W5: Retail | X5: HR | Y5: Business Supprt | Z5: Marketing | AA5: Stylist | AB5: Clothing Management | AC5: Total | AD5: Retail | AE5: HR | AF5: Business Support | AG5: Marketing | AH5: Stylist | AI5: Clothing Management | AJ5: Total
B6: January | C6: =January!C36 -> 46 | D6: =January!D36 -> 39 | E6: =January!E36 -> 8 | F6: =January!F36 -> 31 | G6: =January!G36 -> 0 | H6: =January!H36 -> 33 | I6: =January!I36 -> 27 | J6: =January!J36 -> 7 | ... AJ6: =January!AJ36 -> 931
B7: February | C7: =February!C36 -> 39 | D7: =February!D36 -> 32 | E7: =February!E36 -> 9 | F7: =February!F36 -> 23 | G7: =February!G36 -> 0 | H7: =February!H36 -> 30 | I7: =February!I36 -> 24 | J7: =February!J36 -> 6 | ... AJ7: =February!AJ36 -> 825.5
B8: March | C8: =March!C36 -> 46 | D8: =March!D36 -> 42 | E8: =March!E36 -> 8 | F8: =March!F36 -> 33 | G8: =March!G36 -> 1 | H8: =March!H36 -> 37 | I8: =March!I36 -> 34 | J8: =March!J36 -> 14 | ... AJ8: =March!AJ36 -> 876.5
B9: April | C9: =April!C36 -> 49 | D9: =April!D36 -> 45 | E9: =April!E36 -> 7 | F9: =April!F36 -> 38 | G9: =April!G36 -> 0 | H9: =April!H36 -> 25 | I9: =April!I36 -> 21 | J9: =April!J36 -> 8 | ... AJ9: =April!AJ36 -> 852.5
B10: May | C10: =May!C36 -> 34 | D10: =May!D36 -> 29 | E10: =May!E36 -> 9 | F10: =May!F36 -> 20 | G10: =May!G36 -> 0 | H10: =May!H36 -> 35 | I10: =May!I36 -> 30 | J10: =May!J36 -> 8 | ... AJ10: =May!AJ36 -> 816
B11: June | C11: =June!C36 -> 39 | D11: =June!D36 -> 35 | E11: =June!E36 -> 10 | F11: =June!F36 -> 24 | G11: =June!G36 -> 1 | H11: =June!H36 -> 32 | I11: =June!I36 -> 27 | J11: =June!J36 -> 8 | ... AJ11: =June!AJ36 -> 878.5
B12: July | C12: =July!C36 -> 41 | D12: =July!D36 -> 39 | E12: =July!E36 -> 8 | F12: =July!F36 -> 29 | G12: =July!G36 -> 2 | H12: =July!H36 -> 29 | I12: =July!I36 -> 26 | J12: =July!J36 -> 8 | ... AJ12: =July!AJ36 -> 946
B13: August | C13: =August!C36 -> 46 | D13: =August!D36 -> 44 | E13: =August!E36 -> 9 | F13: =August!F36 -> 35 | G13: =August!G36 -> 0 | H13: =August!H36 -> 40 | I13: =August!I36 -> 33 | J13: =August!J36 -> 9 | ... AJ13: =August!AJ36 -> 941.5
B14: September | C14: =September!C36 -> 45 | D14: =September!D36 -> 39 | E14: =September!E36 -> 5 | F14: =September!F36 -> 34 | G14: =September!G36 -> 0 | H14: =September!H36 -> 30 | I14: =September!I36 -> 26 | J14: =September!J36 -> 10 | ... AJ14: =September!AJ36 -> 924
B15: October | C15: =October!C36 -> 48 | D15: =October!D36 -> 44 | E15: =October!E36 -> 7 | F15: =October!F36 -> 36 | G15: =October!G36 -> 1 | H15: =October!H36 -> 27 | I15: =October!I36 -> 23 | J15: =October!J36 -> 8 | ... AJ15: =October!AJ36 -> 939
B16: November | C16: =November!C36 -> 35 | D16: =November!D36 -> 29 | E16: =November!E36 -> 9 | F16: =November!F36 -> 20 | G16: =November!G36 -> 0 | H16: =November!H36 -> 27 | I16: =November!I36 -> 22 | J16: =November!J36 -> 7 | ... AJ16: =November!AJ36 -> 832
B17: December | C17: =December!C36 -> 33 | D17: =December!D36 -> 25 | E17: =December!E36 -> 9 | F17: =December!F36 -> 16 | G17: =December!G36 -> 0 | H17: =December!H36 -> 39 | I17: =December!I36 -> 30 | J17: =December!J36 -> 7 | ... AJ17: =December!AJ36 -> 903
B18: Grand total | C18: =SUM(C6:C17) -> 501 | D18: =SUM(D6:D17) -> 442 | E18: =SUM(E6:E17) -> 98 | F18: =SUM(F6:F17) -> 339 | G18: =SUM(G6:G17) -> 5 | H18: =SUM(H6:H17) -> 384 | I18: =SUM(I6:I17) -> 323 | J18: =SUM(J6:J17) -> 100 | ... AJ18: =SUM(AJ6:AJ17) -> 10665.5

Sheet Weekly Report
C1: MONTHLY OPERATIONS REPORT - YFS - WELLINGTON HUB
C4: Interview Styling | H4: Confidence Styling | M4: WEV Program | Q4: Donations(kg) | S4: Terrace Income | U4: Marketing | W4: Volunteer Count by category | AD4: Volunteer Hours by category
A5: MONTH | B5: WEEK | C5: Registrations | D5: Completed | E5: Male | F5: Female | G5: Non-Binary | H5: Registrations | I5: Completed | J5: Male | K5: Female | L5: Non-Binary | M5: Registrations | N5: Onboarded | O5: Offboarded | P5: Employed | Q5: Donations Received | R5: Re-Donations | S5: Customers Purchased | T5: Total Income | U5: Social Media Outreach | V5: Social Media Engagement | W5: Retail | X5: HR | Y5: Business Supprt | Z5: Marketing | AA5: Stylist | AB5: Clothing Management | AC5: Total | AD5: Retail | AE5: HR | AF5: Business Support | AG5: Marketing | AH5: Stylist | AI5: Clothing Management | AJ5: Total
A6: January | B6: Week 1 | C6: =January!C11 -> 6 | D6: =January!D11 -> 6 | E6: =January!E11 -> 1 | F6: =January!F11 -> 5 | G6: =January!G11 -> 0 | H6: =January!H11 -> 1 | I6: =January!I11 -> 0 | J6: =January!J11 -> 0 | ... AJ6: =January!AJ11 -> 78
B7: Week 2 | C7: =January!C17 -> 7 | D7: =January!D17 -> 5 | E7: =January!E17 -> 2 | F7: =January!F17 -> 3 | G7: =January!G17 -> 0 | H7: =January!H17 -> 10 | I7: =January!I17 -> 8 | J7: =January!J17 -> 4 | ... AJ7: =January!AJ17 -> 167.5
B8: Week 3 | C8: =January!C23 -> 12 | D8: =January!D23 -> 12 | E8: =January!E23 -> 2 | F8: =January!F23 -> 10 | G8: =January!G23 -> 0 | H8: =January!H23 -> 7 | I8: =January!I23 -> 5 | J8: =January!J23 -> 0 | ... AJ8: =January!AJ23 -> 259.5
B9: Week 4 | C9: =January!C29 -> 12 | D9: =January!D29 -> 8 | E9: =January!E29 -> 3 | F9: =January!F29 -> 5 | G9: =January!G29 -> 0 | H9: =January!H29 -> 9 | I9: =January!I29 -> 8 | J9: =January!J29 -> 1 | ... AJ9: =January!AJ29 -> 229
B10: Week 5 | C10: =January!C35 -> 9 | D10: =January!D35 -> 8 | E10: =January!E35 -> 0 | F10: =January!F35 -> 8 | G10: =January!G35 -> 0 | H10: =January!H35 -> 6 | I10: =January!I35 -> 6 | J10: =January!J35 -> 2 | ... AJ10: =January!AJ35 -> 197
A11: TOTAL | C11: =SUM(C6:C10) -> 46 | D11: =SUM(D6:D10) -> 39 | E11: =SUM(E6:E10) -> 8 | F11: =SUM(F6:F10) -> 31 | G11: =SUM(G6:G10) -> 0 | H11: =SUM(H6:H10) -> 33 | I11: =SUM(I6:I10) -> 27 | J11: =SUM(J6:J10) -> 7 | ... AJ11: =SUM(AJ6:AJ10) -> 931
A12: February | B12: Week 6 | C12: =February!C11 -> 12 | D12: =February!D11 -> 9 | E12: =February!E11 -> 3 | F12: =February!F11 -> 6 | G12: =February!G11 -> 0 | H12: =February!H11 -> 11 | I12: =February!I11 -> 9 | J12: =February!J11 -> 1 | ... AJ12: =February!AJ11 -> 228.5
B13: Week 7 | C13: =February!C17 -> 12 | D13: =February!D17 -> 10 | E13: =February!E17 -> 3 | F13: =February!F17 -> 7 | G13: =February!G17 -> 0 | H13: =February!H17 -> 9 | I13: =February!I17 -> 7 | J13: =February!J17 -> 2 | ... AJ13: =February!AJ17 -> 219
B14: Week 8 | C14: =February!C23 -> 4 | D14: =February!D23 -> 3 | E14: =February!E23 -> 1 | F14: =February!F23 -> 2 | G14: =February!G23 -> 0 | H14: =February!H23 -> 6 | I14: =February!I23 -> 6 | J14: =February!J23 -> 2 | ... AJ14: =February!AJ23 -> 215.5
B15: Week 9 | C15: =February!C29 -> 11 | D15: =February!D29 -> 10 | E15: =February!E29 -> 2 | F15: =February!F29 -> 8 | G15: =February!G29 -> 0 | H15: =February!H29 -> 4 | I15: =February!I29 -> 2 | J15: =February!J29 -> 1 | ... AJ15: =February!AJ29 -> 162.5
B16: Week 10 | C16: =February!C35 -> 0 | D16: =February!D35 -> 0 | E16: =February!E35 -> 0 | F16: =February!F35 -> 0 | G16: =February!G35 -> 0 | H16: =February!H35 -> 0 | I16: =February!I35 -> 0 | J16: =February!J35 -> 0 | ... AJ16: =February!AJ35 -> 0
A17: TOTAL | C17: =SUM(C12:C16) -> 39 | D17: =SUM(D12:D16) -> 32 | E17: =SUM(E12:E16) -> 9 | F17: =SUM(F12:F16) -> 23 | G17: =SUM(G12:G16) -> 0 | H17: =SUM(H12:H16) -> 30 | I17: =SUM(I12:I16) -> 24 | J17: =SUM(J12:J16) -> 6 | ... AJ17: =SUM(AJ12:AJ16) -> 825.5
A18: March | B18: Week 11 | C18: =March!C11 -> 14 | D18: =March!D11 -> 13 | E18: =March!E11 -> 2 | F18: =March!F11 -> 11 | G18: =March!G11 -> 0 | H18: =March!H11 -> 10 | I18: =March!I11 -> 9 | J18: =March!J11 -> 4 | ... AJ18: =March!AJ11 -> 211
B19: Week 12 | C19: =March!C17 -> 5 | D19: =March!D17 -> 3 | E19: =March!E17 -> 0 | F19: =March!F17 -> 3 | G19: =March!G17 -> 0 | H19: =March!H17 -> 7 | I19: =March!I17 -> 6 | J19: =March!J17 -> 3 | ... AJ19: =March!AJ17 -> 189
B20: Week 13 | C20: =March!C23 -> 10 | D20: =March!D23 -> 10 | E20: =March!E23 -> 2 | F20: =March!F23 -> 7 | G20: =March!G23 -> 1 | H20: =March!H23 -> 9 | I20: =March!I23 -> 8 | J20: =March!J23 -> 3 | ... AJ20: =March!AJ23 -> 207
B21: Week 14 | C21: =March!C29 -> 15 | D21: =March!D29 -> 14 | E21: =March!E29 -> 3 | F21: =March!F29 -> 11 | G21: =March!G29 -> 0 | H21: =March!H29 -> 9 | I21: =March!I29 -> 9 | J21: =March!J29 -> 3 | ... AJ21: =March!AJ29 -> 199
B22: Week 15 | C22: =March!C35 -> 2 | D22: =March!D35 -> 2 | E22: =March!E35 -> 1 | F22: =March!F35 -> 1 | G22: =March!G35 -> 0 | H22: =March!H35 -> 2 | I22: =March!I35 -> 2 | J22: =March!J35 -> 1 | ... AJ22: =March!AJ35 -> 70.5
A23: TOTAL | C23: =SUM(C18:C22) -> 46 | D23: =SUM(D18:D22) -> 42 | E23: =SUM(E18:E22) -> 8 | F23: =SUM(F18:F22) -> 33 | G23: =SUM(G18:G22) -> 1 | H23: =SUM(H18:H22) -> 37 | I23: =SUM(I18:I22) -> 34 | J23: =SUM(J18:J22) -> 14 | ... AJ23: =SUM(AJ18:AJ22) -> 876.5
A24: April | B24: Week 16 | C24: =April!C11 -> 8 | D24: =April!D11 -> 7 | E24: =April!E11 -> 1 | F24: =April!F11 -> 6 | G24: =April!G11 -> 0 | H24: =April!H11 -> 3 | I24: =April!I11 -> 3 | J24: =April!J11 -> 1 | ... AJ24: =April!AJ11 -> 138.5
B25: Week 17 | C25: =April!C17 -> 12 | D25: =April!D17 -> 10 | E25: =April!E17 -> 2 | F25: =April!F17 -> 8 | G25: =April!G17 -> 0 | H25: =April!H17 -> 5 | I25: =April!I17 -> 4 | J25: =April!J17 -> 2 | ... AJ25: =April!AJ17 -> 166.5
B26: Week 18 | C26: =April!C23 -> 7 | D26: =April!D23 -> 7 | E26: =April!E23 -> 2 | F26: =April!F23 -> 5 | G26: =April!G23 -> 0 | H26: =April!H23 -> 6 | I26: =April!I23 -> 6 | J26: =April!J23 -> 1 | ... AJ26: =April!AJ23 -> 205
B27: Week 19 | C27: =April!C29 -> 11 | D27: =April!D29 -> 11 | E27: =April!E29 -> 1 | F27: =April!F29 -> 10 | G27: =April!G29 -> 0 | H27: =April!H29 -> 6 | I27: =April!I29 -> 5 | J27: =April!J29 -> 3 | ... AJ27: =April!AJ29 -> 177.5
B28: Week 20 | C28: =April!C35 -> 11 | D28: =April!D35 -> 10 | E28: =April!E35 -> 1 | F28: =April!F35 -> 9 | G28: =April!G35 -> 0 | H28: =April!H35 -> 5 | I28: =April!I35 -> 3 | J28: =April!J35 -> 1 | ... AJ28: =April!AJ35 -> 165
A29: TOTAL | C29: =SUM(C24:C28) -> 49 | D29: =SUM(D24:D28) -> 45 | E29: =SUM(E24:E28) -> 7 | F29: =SUM(F24:F28) -> 38 | G29: =SUM(G24:G28) -> 0 | H29: =SUM(H24:H28) -> 25 | I29: =SUM(I24:I28) -> 21 | J29: =SUM(J24:J28) -> 8 | ... AJ29: =SUM(AJ24:AJ28) -> 852.5
A30: May | B30: Week 21 | C30: =May!C11 -> 3 | D30: =May!D11 -> 3 | E30: =May!E11 -> 1 | F30: =May!F11 -> 2 | G30: =May!G11 -> 0 | H30: =May!H11 -> 3 | I30: =May!I11 -> 2 | J30: =May!J11 -> 0 | ... AJ30: =May!AJ11 -> 58.5
B31: Week 22 | C31: =May!C17 -> 12 | D31: =May!D17 -> 11 | E31: =May!E17 -> 2 | F31: =May!F17 -> 9 | G31: =May!G17 -> 0 | H31: =May!H17 -> 11 | I31: =May!I17 -> 11 | J31: =May!J17 -> 3 | ... AJ31: =May!AJ17 -> 152
B32: Week 23 | C32: =May!C23 -> 9 | D32: =May!D23 -> 7 | E32: =May!E23 -> 3 | F32: =May!F23 -> 4 | G32: =May!G23 -> 0 | H32: =May!H23 -> 5 | I32: =May!I23 -> 4 | J32: =May!J23 -> 1 | ... AJ32: =May!AJ23 -> 222
B33: Week 24 | C33: =May!C29 -> 5 | D33: =May!D29 -> 3 | E33: =May!E29 -> 1 | F33: =May!F29 -> 2 | G33: =May!G29 -> 0 | H33: =May!H29 -> 10 | I33: =May!I29 -> 8 | J33: =May!J29 -> 2 | ... AJ33: =May!AJ29 -> 175.5
B34: Week 25 | C34: =May!C35 -> 5 | D34: =May!D35 -> 5 | E34: =May!E35 -> 2 | F34: =May!F35 -> 3 | G34: =May!G35 -> 0 | H34: =May!H35 -> 6 | I34: =May!I35 -> 5 | J34: =May!J35 -> 2 | ... AJ34: =May!AJ35 -> 208
A35: TOTAL | C35: =SUM(C30:C34) -> 34 | D35: =SUM(D30:D34) -> 29 | E35: =SUM(E30:E34) -> 9 | F35: =SUM(F30:F34) -> 20 | G35: =SUM(G30:G34) -> 0 | H35: =SUM(H30:H34) -> 35 | I35: =SUM(I30:I34) -> 30 | J35: =SUM(J30:J34) -> 8 | ... AJ35: =SUM(AJ30:AJ34) -> 816
A36: June | B36: Week 26 | C36: =June!C11 -> 8 | D36: =June!D11 -> 7 | E36: =June!E11 -> 3 | F36: =June!F11 -> 3 | G36: =June!G11 -> 1 | H36: =June!H11 -> 9 | I36: =June!I11 -> 7 | J36: =June!J11 -> 3 | ... AJ36: =June!AJ11 -> 209
B37: Week 27 | C37: =June!C17 -> 8 | D37: =June!D17 -> 7 | E37: =June!E17 -> 3 | F37: =June!F17 -> 4 | G37: =June!G17 -> 0 | H37: =June!H17 -> 9 | I37: =June!I17 -> 8 | J37: =June!J17 -> 2 | ... AJ37: =June!AJ17 -> 190.5
B38: Week 28 | C38: =June!C23 -> 9 | D38: =June!D23 -> 8 | E38: =June!E23 -> 1 | F38: =June!F23 -> 7 | G38: =June!G23 -> 0 | H38: =June!H23 -> 5 | I38: =June!I23 -> 4 | J38: =June!J23 -> 2 | ... AJ38: =June!AJ23 -> 171.5
B39: Week 29 | C39: =June!C29 -> 11 | D39: =June!D29 -> 10 | E39: =June!E29 -> 2 | F39: =June!F29 -> 8 | G39: =June!G29 -> 0 | H39: =June!H29 -> 6 | I39: =June!I29 -> 6 | J39: =June!J29 -> 1 | ... AJ39: =June!AJ29 -> 242
B40: Week 30 | C40: =June!C35 -> 3 | D40: =June!D35 -> 3 | E40: =June!E35 -> 1 | F40: =June!F35 -> 2 | G40: =June!G35 -> 0 | H40: =June!H35 -> 3 | I40: =June!I35 -> 2 | J40: =June!J35 -> 0 | ... AJ40: =June!AJ35 -> 65.5
A41: TOTAL | C41: =SUM(C36:C40) -> 39 | D41: =SUM(D36:D40) -> 35 | E41: =SUM(E36:E40) -> 10 | F41: =SUM(F36:F40) -> 24 | G41: =SUM(G36:G40) -> 1 | H41: =SUM(H36:H40) -> 32 | I41: =SUM(I36:I40) -> 27 | J41: =SUM(J36:J40) -> 8 | ... L41: =SUM(L36:L40) -> 1 | M41: =SUM(P36:P40) -> 3 | N41: =SUM(Q36:Q40) -> 433 | O41: =SUM(R36:R40) -> 98 | P41: =SUM(S36:S40) -> 285 | Q41: =SUM(S36:S40) -> 285 | R41: =SUM(T36:T40) -> 6499 | S41: =SUM(T36:T40) -> 6499 | T41: =SUM(W36:W40) -> 53 | U41: =SUM(X36:X40) -> 21 | V41: =SUM(Y36:Y40) -> 29 | W41: =SUM(Z36:Z40) -> 14 | X41: =SUM(AA36:AA40) -> 62 | Y41: =SUM(AB36:AB40) -> 65 | Z41: =SUM(AC36:AC40) -> 244 | AA41: =SUM(AD36:AD40) -> 180.5 | ... AJ41: =SUM(AM36:AM40) -> 0
A42: July | B42: Week 31 | C42: =July!C11 -> 7 | D42: =July!D11 -> 7 | E42: =July!E11 -> 1 | F42: =July!F11 -> 5 | G42: =July!G11 -> 1 | H42: =July!H11 -> 5 | I42: =July!I11 -> 5 | J42: =July!J11 -> 1 | ... AJ42: =July!AJ11 -> 119
...

Sheet January
E1: MONTHLY OPERATIONS REPORT - YFS - WELLINGTON HUB
C4: Interview Styling | H4: Confidence Styling | M4: WEV Program | Q4: Donations(kg) | S4: Terrace Income | U4: Marketing | W4: Volunteer Count by category | AD4: Volunteer Hours by category
A5: JANUARY | B5: Date | C5: Registrations | D5: Completed | E5: Male | F5: Female | G5: Non-Binary | H5: Registrations | I5: Completed | J5: Male | K5: Female | L5: Non-Binary | M5: Registrations | N5: Onboarded | O5: Offboarded | P5: Employed | Q5: Donations Received | R5: Re-Donations | S5: Customers Purchased | T5: Total Income | U5: Social Media Outreach | V5: Social Media Engagement | W5: Retail | X5: HR | Y5: Business Supprt | Z5: Marketing | AA5: Stylist | AB5: Clothing Management | AC5: Total | AD5: Retail | AE5: HR | AF5: Business Support | AG5: Marketing | AH5: Stylist | AI5: Clothing Management | AJ5: Total
A6: WEEK 1 | AC6: =SUM(W6:AB6) -> 0 | AJ6: =SUM(AD6:AI6) -> 0
AC8: =SUM(W8:AB8) -> 0 | AJ8: =SUM(AD8:AI8) -> 0
B9: 46023 | C9: 3 | D9: 3 | E9: 0 | F9: 3 | G9: 0 | H9: 1 | I9: 0 | J9: 0 | K9: 0 | L9: 0 | M9: 1 | N9: 0 | O9: 0 | P9: 0 | Q9: 0 | R9: 0 | S9: 3 | T9: 85.25 | U9: 1636 | V9: 153 | W9: 2 | X9: 2 | Y9: 2 | Z9: 0 | AA9: 4 | AB9: 1 | AC9: =SUM(W9:AB9) -> 11 | AD9: 9 | AE9: 7.5 | AF9: 9 | AG9: 0 | AH9: 18.5 | AI9: 4 | AJ9: =SUM(AD9:AI9) -> 48
B10: 46024 | C10: 3 | D10: 3 | E10: 1 | F10: 2 | G10: 0 | H10: 0 | I10: 0 | J10: 0 | K10: 0 | L10: 0 | M10: 1 | N10: 1 | O10: 0 | P10: 0 | Q10: 55.6 | R10: 0 | S10: 17 | T10: 443.68 | U10: 811 | V10: 85 | W10: 3 | X10: 1 | Y10: 0 | Z10: 0 | AA10: 1 | AB10: 3 | AC10: =SUM(W10:AB10) -> 8 | AD10: 13 | AE10: 4 | AF10: 0 | AG10: 0 | AH10: 5.5 | AI10: 7.5 | AJ10: =SUM(AD10:AI10) -> 30
A11: TOTAL | C11: =SUM(C9:C10) -> 6 | D11: =SUM(D9:D10) -> 6 | E11: =SUM(E9:E10) -> 1 | F11: =SUM(F9:F10) -> 5 | G11: =SUM(G9:G10) -> 0 | H11: =SUM(H9:H10) -> 1 | I11: =SUM(I9:I10) -> 0 | J11: =SUM(J9:J10) -> 0 | ... AJ11: =SUM(AJ9:AJ10) -> 78
A12: WEEK 2 | B12: 46027 | C12: 1 | D12: 1 | E12: 1 | F12: 0 | G12: 0 | H12: 2 | I12: 2 | J12: 1 | K12: 1 | L12: 0 | M12: 1 | N12: 0 | O12: 0 | P12: 0 | Q12: 0 | R12: 7.2 | S12: 8 | T12: 211.98 | U12: 295 | V12: 18 | W12: 4 | X12: 1 | Y12: 0 | Z12: 0 | AA12: 4 | AB12: 2 | AC12: =SUM(W12:AB12) -> 11 | AD12: 12.5 | AE12: 2.5 | AF12: 0 | AG12: 0 | AH12: 10.5 | AI12: 9 | AJ12: =SUM(AD12:AI12) -> 34.5
B13: 46028 | C13: 1 | D13: 0 | E13: 0 | F13: 0 | G13: 0 | H13: 2 | I13: 2 | J13: 1 | K13: 1 | L13: 0 | M13: 1 | N13: 0 | O13: 1 | P13: 0 | Q13: 38.9 | R13: 4.9 | S13: 16 | T13: 194.65 | U13: 726 | V13: 69 | W13: 1 | X13: 1 | Y13: 1 | Z13: 0 | AA13: 4 | AB13: 3 | AC13: =SUM(W13:AB13) -> 10 | AD13: 5.5 | AE13: 3.5 | AF13: 4 | AG13: 0 | AH13: 10.5 | AI13: 10.5 | AJ13: =SUM(AD13:AI13) -> 34
B14: 46029 | C14: 4 | D14: 3 | E14: 0 | F14: 3 | G14: 0 | H14: 0 | I14: 0 | J14: 0 | K14: 0 | L14: 0 | M14: 0 | N14: 0 | O14: 0 | P14: 0 | Q14: 20.9 | R14: 5.6 | S14: 9 | T14: 256.81 | U14: 1368 | V14: 72 | W14: 4 | X14: 0 | Y14: 2 | Z14: 1 | AA14: 2 | AB14: 3 | AC14: =SUM(W14:AB14) -> 12 | AD14: 9 | AE14: 0 | AF14: 7.5 | AG14: 2.5 | AH14: 4.5 | AI14: 8.5 | AJ14: =SUM(AD14:AI14) -> 32
B15: 46030 | C15: 1 | D15: 1 | E15: 1 | F15: 0 | G15: 0 | H15: 3 | I15: 2 | J15: 1 | K15: 1 | L15: 0 | M15: 0 | N15: 1 | O15: 1 | P15: 0 | Q15: 27.7 | R15: 6.7 | S15: 16 | T15: 320.91 | U15: 1839 | V15: 232 | W15: 1 | X15: 1 | Y15: 0 | Z15: 0 | AA15: 1 | AB15: 4 | AC15: =SUM(W15:AB15) -> 7 | AD15: 4 | AE15: 4.5 | AF15: 0 | AG15: 0 | AH15: 3.5 | AI15: 11.5 | AJ15: =SUM(AD15:AI15) -> 23.5
B16: 46031 | C16: 0 | D16: 0 | E16: 0 | F16: 0 | G16: 0 | H16: 3 | I16: 2 | J16: 1 | K16: 1 | L16: 0 | M16: 0 | N16: 0 | O16: 1 | P16: 0 | Q16: 63.3 | R16: 16.1 | S16: 16 | T16: 200.85 | U16: 1285 | V16: 142 | W16: 3 | X16: 0 | Y16: 2 | Z16: 1 | AA16: 2 | AB16: 2 | AC16: =SUM(W16:AB16) -> 10 | AD16: 10.5 | AE16: 0 | AF16: 9 | AG16: 3 | AH16: 10.5 | AI16: 10.5 | AJ16: =SUM(AD16:AI16) -> 43.5
A17: TOTAL | C17: =SUM(C12:C16) -> 7 | D17: =SUM(D12:D16) -> 5 | E17: =SUM(E12:E16) -> 2 | F17: =SUM(F12:F16) -> 3 | G17: =SUM(G12:G16) -> 0 | H17: =SUM(H12:H16) -> 10 | I17: =SUM(I12:I16) -> 8 | J17: =SUM(J12:J16) -> 4 | ... AJ17: =SUM(AJ12:AJ16) -> 167.5
A18: WEEK 3 | B18: 46034 | C18: 2 | D18: 2 | E18: 0 | F18: 2 | G18: 0 | H18: 2 | I18: 2 | J18: 0 | K18: 2 | L18: 0 | M18: 1 | N18: 0 | O18: 1 | P18: 0 | Q18: 25.5 | R18: 8.1 | S18: 11 | T18: 141.98 | U18: 970 | V18: 52 | W18: 4 | X18: 1 | Y18: 0 | Z18: 1 | AA18: 3 | AB18: 3 | AC18: =SUM(W18:AB18) -> 12 | AD18: 20.5 | AE18: 2.5 | AF18: 0 | AG18: 3.5 | AH18: 15.5 | AI18: 14.5 | AJ18: =SUM(AD18:AI18) -> 56.5
B19: 46035 | C19: 3 | D19: 3 | E19: 1 | F19: 2 | G19: 0 | H19: 0 | I19: 0 | J19: 0 | K19: 0 | L19: 0 | M19: 0 | N19: 0 | O19: 0 | P19: 1 | Q19: 59.4 | R19: 7.7 | S19: 11 | T19: 275.98 | U19: 1484 | V19: 151 | W19: 2 | X19: 0 | Y19: 2 | Z19: 1 | AA19: 5 | AB19: 2 | AC19: =SUM(W19:AB19) -> 12 | AD19: 6.5 | AE19: 0 | AF19: 9 | AG19: 4 | AH19: 17 | AI19: 8.5 | AJ19: =SUM(AD19:AI19) -> 45
B20: 46036 | C20: 1 | D20: 1 | E20: 0 | F20: 1 | G20: 0 | H20: 1 | I20: 1 | J20: 0 | K20: 1 | L20: 0 | M20: 0 | N20: 1 | O20: 1 | P20: 0 | Q20: 0 | R20: 0 | S20: 17 | T20: 459.37 | U20: 793 | V20: 85 | W20: 2 | X20: 2 | Y20: 1 | Z20: 2 | AA20: 4 | AB20: 2 | AC20: =SUM(W20:AB20) -> 13 | AD20: 7.5 | AE20: 7.5 | AF20: 5.5 | AG20: 6.5 | AH20: 11.5 | AI20: 5.5 | AJ20: =SUM(AD20:AI20) -> 44
B21: 46037 | C21: 2 | D21: 2 | E21: 0 | F21: 2 | G21: 0 | H21: 3 | I21: 2 | J21: 0 | K21: 2 | L21: 0 | M21: 2 | N21: 0 | O21: 0 | P21: 0 | Q21: 0 | R21: 8.2 | S21: 3 | T21: 65.75 | U21: 736 | V21: 15 | W21: 4 | X21: 0 | Y21: 1 | Z21: 1 | AA21: 3 | AB21: 4 | AC21: =SUM(W21:AB21) -> 13 | AD21: 13 | AE21: 0 | AF21: 3 | AG21: 4.5 | AH21: 13 | AI21: 21.5 | AJ21: =SUM(AD21:AI21) -> 55
B22: 46038 | C22: 4 | D22: 4 | E22: 1 | F22: 3 | G22: 0 | H22: 1 | I22: 0 | J22: 0 | K22: 0 | L22: 0 | M22: 1 | N22: 1 | O22: 0 | P22: 0 | Q22: 0 | R22: 17.3 | S22: 15 | T22: 435.96 | U22: 1100 | V22: 169 | W22: 4 | X22: 1 | Y22: 2 | Z22: 0 | AA22: 5 | AB22: 4 | AC22: =SUM(W22:AB22) -> 16 | AD22: 9 | AE22: 3.5 | AF22: 6.5 | AG22: 0 | AH22: 23 | AI22: 17 | AJ22: =SUM(AD22:AI22) -> 59
A23: TOTAL | C23: =SUM(C18:C22) -> 12 | D23: =SUM(D18:D22) -> 12 | E23: =SUM(E18:E22) -> 2 | F23: =SUM(F18:F22) -> 10 | G23: =SUM(G18:G22) -> 0 | H23: =SUM(H18:H22) -> 7 | I23: =SUM(I18:I22) -> 5 | J23: =SUM(J18:J22) -> 0 | ... AJ23: =SUM(AJ18:AJ22) -> 259.5
A24: WEEK 4 | B24: 46041 | C24: 1 | D24: 1 | E24: 1 | F24: 0 | G24: 0 | H24: 2 | I24: 1 | J24: 1 | K24: 0 | L24: 0 | M24: 0 | N24: 0 | O24: 0 | P24: 0 | Q24: 64.2 | R24: 21.7 | S24: 7 | T24: 119.69 | U24: 1693 | V24: 108 | W24: 4 | X24: 0 | Y24: 1 | Z24: 1 | AA24: 4 | AB24: 3 | AC24: =SUM(W24:AB24) -> 13 | AD24: 22 | AE24: 0 | AF24: 5.5 | AG24: 3.5 | AH24: 22 | AI24: 12 | AJ24: =SUM(AD24:AI24) -> 65
B25: 46042 | C25: 3 | D25: 2 | E25: 1 | F25: 1 | G25: 0 | H25: 3 | I25: 3 | J25: 0 | K25: 3 | L25: 0 | M25: 1 | N25: 0 | O25: 0 | P25: 0 | Q25: 42.1 | R25: 0 | S25: 13 | T25: 263.1 | U25: 2009 | V25: 178 | W25: 3 | X25: 0 | Y25: 2 | Z25: 0 | AA25: 2 | AB25: 1 | AC25: =SUM(W25:AB25) -> 8 | AD25: 13 | AE25: 0 | AF25: 8 | AG25: 0 | AH25: 5 | AI25: 5 | AJ25: =SUM(AD25:AI25) -> 31
B26: 46043 | C26: 2 | D26: 1 | E26: 0 | F26: 1 | G26: 0 | H26: 2 | I26: 2 | J26: 0 | K26: 2 | L26: 0 | M26: 2 | N26: 1 | O26: 0 | P26: 0 | Q26: 8.3 | R26: 10 | S26: 19 | T26: 551.37 | U26: 2010 | V26: 229 | W26: 3 | X26: 1 | Y26: 1 | Z26: 2 | AA26: 4 | AB26: 1 | AC26: =SUM(W26:AB26) -> 12 | AD26: 11.5 | AE26: 3.5 | AF26: 2 | AG26: 6 | AH26: 10.5 | AI26: 5 | AJ26: =SUM(AD26:AI26) -> 38.5
B27: 46044 | C27: 4 | D27: 3 | E27: 1 | F27: 2 | G27: 0 | H27: 2 | I27: 2 | J27: 0 | K27: 2 | L27: 0 | M27: 1 | N27: 0 | O27: 1 | P27: 0 | Q27: 24.4 | R27: 0 | S27: 19 | T27: 441.99 | U27: 1740 | V27: 82 | W27: 4 | X27: 1 | Y27: 2 | Z27: 0 | AA27: 5 | AB27: 4 | AC27: =SUM(W27:AB27) -> 16 | AD27: 12.5 | AE27: 5.5 | AF27: 7 | AG27: 0 | AH27: 19 | AI27: 19.5 | AJ27: =SUM(AD27:AI27) -> 63.5
B28: 46045 | C28: 2 | D28: 1 | E28: 0 | F28: 1 | G28: 0 | H28: 0 | I28: 0 | J28: 0 | K28: 0 | L28: 0 | M28: 2 | N28: 0 | O28: 0 | P28: 0 | Q28: 51.5 | R28: 0 | S28: 7 | T28: 183.48 | U28: 284 | V28: 44 | W28: 1 | X28: 2 | Y28: 2 | Z28: 0 | AA28: 1 | AB28: 1 | AC28: =SUM(W28:AB28) -> 7 | AD28: 5 | AE28: 10.5 | AF28: 7 | AG28: 0 | AH28: 5 | AI28: 3.5 | AJ28: =SUM(AD28:AI28) -> 31
A29: TOTAL | C29: =SUM(C24:C28) -> 12 | D29: =SUM(D24:D28) -> 8 | E29: =SUM(E24:E28) -> 3 | F29: =SUM(F24:F28) -> 5 | G29: =SUM(G24:G28) -> 0 | H29: =SUM(H24:H28) -> 9 | I29: =SUM(I24:I28) -> 8 | J29: =SUM(J24:J28) -> 1 | ... AJ29: =SUM(AJ24:AJ28) -> 229
A30: WEEK 5 | B30: 46048 | C30: 4 | D30: 4 | E30: 0 | F30: 4 | G30: 0 | H30: 3 | I30: 3 | J30: 0 | K30: 3 | L30: 0 | M30: 1 | N30: 0 | O30: 0 | P30: 0 | Q30: 29.2 | R30: 14.6 | S30: 15 | T30: 385.96 | U30: 1249 | V30: 110 | W30: 4 | X30: 1 | Y30: 1 | Z30: 1 | AA30: 1 | AB30: 1 | AC30: =SUM(W30:AB30) -> 9 | AD30: 16.5 | AE30: 3.5 | AF30: 5 | AG30: 4 | AH30: 4 | AI30: 3.5 | AJ30: =SUM(AD30:AI30) -> 36.5
B31: 46049 | C31: 1 | D31: 0 | E31: 0 | F31: 0 | G31: 0 | H31: 2 | I31: 2 | J31: 1 | K31: 1 | L31: 0 | M31: 1 | N31: 1 | O31: 0 | P31: 1 | Q31: 63.4 | R31: 0 | S31: 21 | T31: 584.15 | U31: 342 | V31: 27 | W31: 1 | X31: 1 | Y31: 1 | Z31: 1 | AA31: 2 | AB31: 4 | AC31: =SUM(W31:AB31) -> 10 | AD31: 3.5 | AE31: 2.5 | AF31: 2.5 | AG31: 3 | AH31: 9.5 | AI31: 11 | AJ31: =SUM(AD31:AI31) -> 32
B32: 46050 | C32: 0 | D32: 0 | E32: 0 | F32: 0 | G32: 0 | H32: 0 | I32: 0 | J32: 0 | K32: 0 | L32: 0 | M32: 1 | N32: 0 | O32: 0 | P32: 0 | Q32: 16.8 | R32: 5.6 | S32: 9 | T32: 257.09 | U32: 1434 | V32: 229 | W32: 1 | X32: 1 | Y32: 0 | Z32: 2 | AA32: 4 | AB32: 1 | AC32: =SUM(W32:AB32) -> 9 | AD32: 4 | AE32: 3.5 | AF32: 0 | AG32: 11 | AH32: 21 | AI32: 3.5 | AJ32: =SUM(AD32:AI32) -> 43
B33: 46051 | C33: 1 | D33: 1 | E33: 0 | F33: 1 | G33: 0 | H33: 1 | I33: 1 | J33: 1 | K33: 0 | L33: 0 | M33: 2 | N33: 0 | O33: 0 | P33: 0 | Q33: 25.9 | R33: 0 | S33: 7 | T33: 134.11 | U33: 2025 | V33: 247 | W33: 4 | X33: 2 | Y33: 1 | Z33: 2 | AA33: 1 | AB33: 2 | AC33: =SUM(W33:AB33) -> 12 | AD33: 10 | AE33: 10 | AF33: 3 | AG33: 11 | AH33: 3.5 | AI33: 5.5 | AJ33: =SUM(AD33:AI33) -> 43
B34: 46052 | C34: 3 | D34: 3 | E34: 0 | F34: 3 | G34: 0 | H34: 0 | I34: 0 | J34: 0 | K34: 0 | L34: 0 | M34: 0 | N34: 0 | O34: 0 | P34: 0 | Q34: 50.9 | R34: 5.8 | S34: 15 | T34: 299.35 | U34: 1844 | V34: 87 | W34: 2 | X34: 2 | Y34: 0 | Z34: 0 | AA34: 4 | AB34: 4 | AC34: =SUM(W34:AB34) -> 12 | AD34: 5 | AE34: 7.5 | AF34: 0 | AG34: 0 | AH34: 8.5 | AI34: 21.5 | AJ34: =SUM(AD34:AI34) -> 42.5
A35: TOTAL | C35: =SUM(C30:C34) -> 9 | D35: =SUM(D30:D34) -> 8 | E35: =SUM(E30:E34) -> 0 | F35: =SUM(F30:F34) -> 8 | G35: =SUM(G30:G34) -> 0 | H35: =SUM(H30:H34) -> 6 | I35: =SUM(I30:I34) -> 6 | J35: =SUM(J30:J34) -> 2 | ... AJ35: =SUM(AJ30:AJ34) -> 197
A36: JANUARY-GRAND TOTAL | C36: =C11+C17+C23+C29+C35 -> 46 | D36: =D11+D17+D23+D29+D35 -> 39 | E36: =E11+E17+E23+E29+E35 -> 8 | F36: =F11+F17+F23+F29+F35 -> 31 | G36: =G11+G17+G23+G29+G35 -> 0 | H36: =H11+H17+H23+H29+H35 -> 33 | I36: =I11+I17+I23+I29+I35 -> 27 | J36: =J11+J17+J23+J29+J35 -> 7 | ... AJ36: =AJ11+AJ17+AJ23+AJ29+AJ35 -> 931
H41: =UPPER(G41)

Sheet February
E1: MONTHLY OPERATIONS REPORT - YFS - WELLINGTON HUB
C4: Interview Styling | H4: Confidence Styling | M4: WEV Program | Q4: Donations(kg) | S4: Terrace Income | U4: Marketing | W4: Volunteer Count by category | AD4: Volunteer Hours by category
A5: FEBRUARY | B5: Date | C5: Registrations | D5: Completed | E5: Male | F5: Female | G5: Non-Binary | H5: Registrations | I5: Completed | J5: Male | K5: Female | L5: Non-Binary | M5: Registrations | N5: Onboarded | O5: Offboarded | P5: Employed | Q5: Donations Received | R5: Re-Donations | S5: Customers Purchased | T5: Total Income | U5: Social Media Outreach | V5: Social Media Engagement | W5: Retail | X5: HR | Y5: Business Supprt | Z5: Marketing | AA5: Stylist | AB5: Clothing Management | AC5: Total | AD5: Retail | AE5: HR | AF5: Business Support | AG5: Marketing | AH5: Stylist | AI5: Clothing Management | AJ5: Total
A6: WEEK 1 | B6: 46055 | C6: 1 | D6: 0 | E6: 0 | F6: 0 | G6: 0 | H6: 3 | I6: 3 | J6: 0 | K6: 3 | L6: 0 | M6: 1 | N6: 0 | O6: 0 | P6: 0 | Q6: 26.9 | R6: 0 | S6: 20 | T6: 596.72 | U6: 1197 | V6: 170 | W6: 1 | X6: 0 | Y6: 2 | Z6: 0 | AA6: 5 | AB6: 3 | AC6: =SUM(W6:AB6) -> 11 | AD6: 3.5 | AE6: 0 | AF6: 8.5 | AG6: 0 | AH6: 25 | AI6: 8 | AJ6: =SUM(AD6:AI6) -> 45
B7: 46056 | C7: 3 | D7: 3 | E7: 1 | F7: 2 | G7: 0 | H7: 2 | I7: 1 | J7: 1 | K7: 0 | L7: 0 | M7: 0 | N7: 0 | O7: 0 | P7: 0 | Q7: 15.2 | R7: 2.3 | S7: 19 | T7: 395.6 | U7: 1945 | V7: 195 | W7: 4 | X7: 0 | Y7: 1 | Z7: 1 | AA7: 4 | AB7: 4 | AC7: =SUM(W7:AB7) -> 14 | AD7: 20.5 | AE7: 0 | AF7: 4.5 | AG7: 4.5 | AH7: 11.5 | AI7: 11.5 | AJ7: =SUM(AD7:AI7) -> 52.5
B8: 46057 | C8: 2 | D8: 2 | E8: 1 | F8: 1 | G8: 0 | H8: 3 | I8: 3 | J8: 0 | K8: 3 | L8: 0 | M8: 1 | N8: 0 | O8: 0 | P8: 0 | Q8: 16.6 | R8: 0 | S8: 6 | T8: 175.84 | U8: 603 | V8: 30 | W8: 3 | X8: 0 | Y8: 0 | Z8: 2 | AA8: 2 | AB8: 3 | AC8: =SUM(W8:AB8) -> 10 | AD8: 6.5 | AE8: 0 | AF8: 0 | AG8: 5.5 | AH8: 8.5 | AI8: 7 | AJ8: =SUM(AD8:AI8) -> 27.5
B9: 46058 | C9: 2 | D9: 1 | E9: 0 | F9: 1 | G9: 0 | H9: 2 | I9: 1 | J9: 0 | K9: 1 | L9: 0 | M9: 0 | N9: 1 | O9: 0 | P9: 0 | Q9: 33 | R9: 0 | S9: 20 | T9: 372.35 | U9: 1793 | V9: 237 | W9: 2 | X9: 0 | Y9: 1 | Z9: 1 | AA9: 5 | AB9: 4 | AC9: =SUM(W9:AB9) -> 13 | AD9: 7 | AE9: 0 | AF9: 3.5 | AG9: 5 | AH9: 16.5 | AI9: 20 | AJ9: =SUM(AD9:AI9) -> 52
B10: 46059 | C10: 4 | D10: 3 | E10: 1 | F10: 2 | G10: 0 | H10: 1 | I10: 1 | J10: 0 | K10: 1 | L10: 0 | M10: 1 | N10: 0 | O10: 0 | P10: 0 | Q10: 55.2 | R10: 0 | S10: 14 | T10: 271.02 | U10: 944 | V10: 107 | W10: 2 | X10: 2 | Y10: 2 | Z10: 1 | AA10: 5 | AB10: 3 | AC10: =SUM(W10:AB10) -> 15 | AD10: 5 | AE10: 10.5 | AF10: 10 | AG10: 3 | AH10: 16.5 | AI10: 6.5 | AJ10: =SUM(AD10:AI10) -> 51.5
A11: TOTAL | C11: =SUM(C6:C10) -> 12 | D11: =SUM(D6:D10) -> 9 | E11: =SUM(E6:E10) -> 3 | F11: =SUM(F6:F10) -> 6 | G11: =SUM(G6:G10) -> 0 | H11: =SUM(H6:H10) -> 11 | I11: =SUM(I6:I10) -> 9 | J11: =SUM(J6:J10) -> 1 | ... AJ11: =SUM(AJ6:AJ10) -> 228.5
A12: WEEK 2 | B12: 46062 | C12: 4 | D12: 4 | E12: 0 | F12: 4 | G12: 0 | H12: 1 | I12: 1 | J12: 1 | K12: 0 | L12: 0 | M12: 0 | N12: 1 | O12: 0 | P12: 0 | Q12: 0 | R12: 15.9 | S12: 22 | T12: 437.38 | U12: 1799 | V12: 122 | W12: 2 | X12: 1 | Y12: 0 | Z12: 2 | AA12: 4 | AB12: 1 | AC12: =SUM(W12:AB12) -> 10 | AD12: 8.5 | AE12: 3.5 | AF12: 0 | AG12: 7.5 | AH12: 12 | AI12: 4.5 | AJ12: =SUM(AD12:AI12) -> 36
B13: 46063 | C13: 2 | D13: 1 | E13: 1 | F13: 0 | G13: 0 | H13: 3 | I13: 3 | J13: 0 | K13: 3 | L13: 0 | M13: 1 | N13: 0 | O13: 1 | P13: 0 | Q13: 29.5 | R13: 0 | S13: 16 | T13: 299.31 | U13: 1000 | V13: 146 | W13: 4 | X13: 1 | Y13: 1 | Z13: 0 | AA13: 1 | AB13: 2 | AC13: =SUM(W13:AB13) -> 9 | AD13: 18.5 | AE13: 4.5 | AF13: 4 | AG13: 0 | AH13: 4.5 | AI13: 5.5 | AJ13: =SUM(AD13:AI13) -> 37
B14: 46064 | C14: 4 | D14: 3 | E14: 1 | F14: 2 | G14: 0 | H14: 1 | I14: 1 | J14: 0 | K14: 1 | L14: 0 | M14: 2 | N14: 1 | O14: 1 | P14: 0 | Q14: 56 | R14: 0 | S14: 19 | T14: 318.2 | U14: 1717 | V14: 96 | W14: 1 | X14: 1 | Y14: 1 | Z14: 1 | AA14: 4 | AB14: 4 | AC14: =SUM(W14:AB14) -> 12 | AD14: 4 | AE14: 5.5 | AF14: 2.5 | AG14: 3 | AH14: 16.5 | AI14: 8.5 | AJ14: =SUM(AD14:AI14) -> 40
B15: 46065 | C15: 0 | D15: 0 | E15: 0 | F15: 0 | G15: 0 | H15: 3 | I15: 2 | J15: 1 | K15: 1 | L15: 0 | M15: 0 | N15: 0 | O15: 0 | P15: 0 | Q15: 58.4 | R15: 0 | S15: 4 | T15: 85.12 | U15: 711 | V15: 34 | W15: 1 | X15: 1 | Y15: 2 | Z15: 2 | AA15: 2 | AB15: 4 | AC15: =SUM(W15:AB15) -> 12 | AD15: 4 | AE15: 3 | AF15: 7.5 | AG15: 10 | AH15: 9 | AI15: 18.5 | AJ15: =SUM(AD15:AI15) -> 52
B16: 46066 | C16: 2 | D16: 2 | E16: 1 | F16: 1 | G16: 0 | H16: 1 | I16: 0 | J16: 0 | K16: 0 | L16: 0 | M16: 0 | N16: 0 | O16: 0 | P16: 0 | Q16: 0 | R16: 0 | S16: 3 | T16: 73.16 | U16: 1359 | V16: 157 | W16: 3 | X16: 2 | Y16: 2 | Z16: 0 | AA16: 4 | AB16: 2 | AC16: =SUM(W16:AB16) -> 13 | AD16: 9.5 | AE16: 10.5 | AF16: 6 | AG16: 0 | AH16: 20 | AI16: 8 | AJ16: =SUM(AD16:AI16) -> 54
A17: TOTAL | C17: =SUM(C12:C16) -> 12 | D17: =SUM(D12:D16) -> 10 | E17: =SUM(E12:E16) -> 3 | F17: =SUM(F12:F16) -> 7 | G17: =SUM(G12:G16) -> 0 | H17: =SUM(H12:H16) -> 9 | I17: =SUM(I12:I16) -> 7 | J17: =SUM(J12:J16) -> 2 | ... AJ17: =SUM(AJ12:AJ16) -> 219
A18: WEEK 3 | B18: 46069 | C18: 1 | D18: 0 | E18: 0 | F18: 0 | G18: 0 | H18: 3 | I18: 3 | J18: 1 | K18: 2 | L18: 0 | M18: 0 | N18: 0 | O18: 0 | P18: 0 | Q18: 0 | R18: 6.2 | S18: 10 | T18: 236.8 | U18: 1386 | V18: 75 | W18: 1 | X18: 0 | Y18: 1 | Z18: 2 | AA18: 4 | AB18: 4 | AC18: =SUM(W18:AB18) -> 12 | AD18: 5 | AE18: 0 | AF18: 2 | AG18: 4.5 | AH18: 18.5 | AI18: 21 | AJ18: =SUM(AD18:AI18) -> 51
B19: 46070 | C19: 0 | D19: 0 | E19: 0 | F19: 0 | G19: 0 | H19: 2 | I19: 2 | J19: 0 | K19: 2 | L19: 0 | M19: 0 | N19: 0 | O19: 1 | P19: 1 | Q19: 63.8 | R19: 0 | S19: 19 | T19: 545.29 | U19: 1626 | V19: 56 | W19: 2 | X19: 0 | Y19: 0 | Z19: 1 | AA19: 3 | AB19: 1 | AC19: =SUM(W19:AB19) -> 7 | AD19: 9 | AE19: 0 | AF19: 0 | AG19: 2 | AH19: 7 | AI19: 3.5 | AJ19: =SUM(AD19:AI19) -> 21.5
B20: 46071 | C20: 0 | D20: 0 | E20: 0 | F20: 0 | G20: 0 | H20: 0 | I20: 0 | J20: 0 | K20: 0 | L20: 0 | M20: 0 | N20: 1 | O20: 1 | P20: 0 | Q20: 44.6 | R20: 0 | S20: 20 | T20: 417.44 | U20: 1336 | V20: 128 | W20: 3 | X20: 0 | Y20: 0 | Z20: 1 | AA20: 5 | AB20: 4 | AC20: =SUM(W20:AB20) -> 13 | AD20: 9 | AE20: 0 | AF20: 0 | AG20: 3 | AH20: 23 | AI20: 17.5 | AJ20: =SUM(AD20:AI20) -> 52.5
B21: 46072 | C21: 3 | D21: 3 | E21: 1 | F21: 2 | G21: 0 | H21: 0 | I21: 0 | J21: 0 | K21: 0 | L21: 0 | M21: 0 | N21: 1 | O21: 0 | P21: 0 | Q21: 0 | R21: 0 | S21: 9 | T21: 243.75 | U21: 2051 | V21: 210 | W21: 1 | X21: 1 | Y21: 2 | Z21: 2 | AA21: 3 | AB21: 2 | AC21: =SUM(W21:AB21) -> 11 | AD21: 4.5 | AE21: 5.5 | AF21: 8.5 | AG21: 7 | AH21: 6.5 | AI21: 7.5 | AJ21: =SUM(AD21:AI21) -> 39.5
B22: 46073 | C22: 0 | D22: 0 | E22: 0 | F22: 0 | G22: 0 | H22: 1 | I22: 1 | J22: 1 | K22: 0 | L22: 0 | M22: 0 | N22: 0 | O22: 1 | P22: 0 | Q22: 17.8 | R22: 0 | S22: 3 | T22: 103.25 | U22: 525 | V22: 40 | W22: 2 | X22: 2 | Y22: 1 | Z22: 0 | AA22: 5 | AB22: 3 | AC22: =SUM(W22:AB22) -> 13 | AD22: 4.5 | AE22: 8 | AF22: 4.5 | AG22: 0 | AH22: 18.5 | AI22: 15.5 | AJ22: =SUM(AD22:AI22) -> 51
A23: TOTAL | C23: =SUM(C18:C22) -> 4 | D23: =SUM(D18:D22) -> 3 | E23: =SUM(E18:E22) -> 1 | F23: =SUM(F18:F22) -> 2 | G23: =SUM(G18:G22) -> 0 | H23: =SUM(H18:H22) -> 6 | I23: =SUM(I18:I22) -> 6 | J23: =SUM(J18:J22) -> 2 | ... AJ23: =SUM(AJ18:AJ22) -> 215.5
A24: WEEK 4 | B24: 46076 | C24: 3 | D24: 3 | E24: 0 | F24: 3 | G24: 0 | H24: 1 | I24: 1 | J24: 0 | K24: 1 | L24: 0 | M24: 1 | N24: 0 | O24: 0 | P24: 0 | Q24: 62.7 | R24: 14.7 | S24: 10 | T24: 256.27 | U24: 259 | V24: 18 | W24: 2 | X24: 1 | Y24: 1 | Z24: 0 | AA24: 5 | AB24: 1 | AC24: =SUM(W24:AB24) -> 10 | AD24: 9.5 | AE24: 2 | AF24: 4.5 | AG24: 0 | AH24: 14.5 | AI24: 2.5 | AJ24: =SUM(AD24:AI24) -> 33
B25: 46077 | C25: 3 | D25: 3 | E25: 1 | F25: 2 | G25: 0 | H25: 1 | I25: 1 | J25: 1 | K25: 0 | L25: 0 | M25: 1 | N25: 0 | O25: 1 | P25: 1 | Q25: 13.7 | R25: 20.7 | S25: 3 | T25: 109.16 | U25: 514 | V25: 21 | W25: 4 | X25: 1 | Y25: 1 | Z25: 0 | AA25: 1 | AB25: 3 | AC25: =SUM(W25:AB25) -> 10 | AD25: 19.5 | AE25: 3.5 | AF25: 2.5 | AG25: 0 | AH25: 3 | AI25: 12.5 | AJ25: =SUM(AD25:AI25) -> 41
B26: 46078 | C26: 4 | D26: 4 | E26: 1 | F26: 3 | G26: 0 | H26: 1 | I26: 0 | J26: 0 | K26: 0 | L26: 0 | M26: 1 | N26: 0 | O26: 0 | P26: 0 | Q26: 54.5 | R26: 0 | S26: 10 | T26: 283.15 | U26: 2047 | V26: 202 | W26: 1 | X26: 0 | Y26: 1 | Z26: 0 | AA26: 2 | AB26: 1 | AC26: =SUM(W26:AB26) -> 5 | AD26: 3 | AE26: 0 | AF26: 4 | AG26: 0 | AH26: 5 | AI26: 4.5 | AJ26: =SUM(AD26:AI26) -> 16.5
B27: 46079 | C27: 1 | D27: 0 | E27: 0 | F27: 0 | G27: 0 | H27: 1 | I27: 0 | J27: 0 | K27: 0 | L27: 0 | M27: 2 | N27: 1 | O27: 0 | P27: 1 | Q27: 47.5 | R27: 0 | S27: 12 | T27: 258.99 | U27: 685 | V27: 22 | W27: 1 | X27: 1 | Y27: 1 | Z27: 0 | AA27: 4 | AB27: 4 | AC27: =SUM(W27:AB27) -> 11 | AD27: 4 | AE27: 4.5 | AF27: 3.5 | AG27: 0 | AH27: 13.5 | AI27: 19 | AJ27: =SUM(AD27:AI27) -> 44.5
B28: 46080 | C28: 0 | D28: 0 | E28: 0 | F28: 0 | G28: 0 | H28: 0 | I28: 0 | J28: 0 | K28: 0 | L28: 0 | M28: 1 | N28: 0 | O28: 0 | P28: 0 | Q28: 40.5 | R28: 19 | S28: 11 | T28: 216.28 | U28: 433 | V28: 12 | W28: 2 | X28: 0 | Y28: 0 | Z28: 2 | AA28: 2 | AB28: 2 | AC28: =SUM(W28:AB28) -> 8 | AD28: 5.5 | AE28: 0 | AF28: 0 | AG28: 6.5 | AH28: 11 | AI28: 4.5 | AJ28: =SUM(AD28:AI28) -> 27.5
A29: TOTAL | C29: =SUM(C24:C28) -> 11 | D29: =SUM(D24:D28) -> 10 | E29: =SUM(E24:E28) -> 2 | F29: =SUM(F24:F28) -> 8 | G29: =SUM(G24:G28) -> 0 | H29: =SUM(H24:H28) -> 4 | I29: =SUM(I24:I28) -> 2 | J29: =SUM(J24:J28) -> 1 | ... AJ29: =SUM(AJ24:AJ28) -> 162.5
A30: WEEK 5 | AC30: =SUM(W30:AB30) -> 0 | AJ30: =SUM(AD30:AI30) -> 0
AC31: =SUM(W31:AB31) -> 0 | AJ31: =SUM(AD31:AI31) -> 0
AC32: =SUM(W32:AB32) -> 0 | AJ32: =SUM(AD32:AI32) -> 0
AC33: =SUM(W33:AB33) -> 0 | AJ33: =SUM(AD33:AI33) -> 0
AC34: =SUM(W34:AB34) -> 0 | AJ34: =SUM(AD34:AI34) -> 0
A35: TOTAL | C35: 0 | D35: 0 | E35: 0 | F35: 0 | G35: 0 | H35: =SUM(H30:H34) -> 0 | I35: =SUM(I30:I34) -> 0 | J35: =SUM(J30:J34) -> 0 | K35: =SUM(K30:K34) -> 0 | L35: =SUM(L30:L34) -> 0 | M35: =SUM(M30:M34) -> 0 | N35: =SUM(N30:N34) -> 0 | O35: =SUM(O30:O34) -> 0 | ... AJ35: =SUM(AJ30:AJ34) -> 0
A36: FEBRUARY-GRAND TOTAL | C36: =C11+C17+C23+C29+C35 -> 39 | D36: =D11+D17+D23+D29+D35 -> 32 | E36: =E11+E17+E23+E29+E35 -> 9 | F36: =F11+F17+F23+F29+F35 -> 23 | G36: =G11+G17+G23+G29+G35 -> 0 | H36: =H11+H17+H23+H29+H35 -> 30 | I36: =I11+I17+I23+I29+I35 -> 24 | J36: =J11+J17+J23+J29+J35 -> 6 | ... AJ36: =AJ11+AJ17+AJ23+AJ29+AJ35 -> 825.5
A39: References:
A40: Events:Wix.com

Sheet March
E1: MONTHLY OPERATIONS REPORT - YFS - WELLINGTON HUB
C4: Interview Styling | H4: Confidence Styling | M4: WEV Program | Q4: Donations(kg) | S4: Terrace Income | U4: Marketing | W4: Volunteer Count by category | AD4: Volunteer Hours by category
A5: MARCH | B5: Date | C5: Registrations | D5: Completed | E5: Male | F5: Female | G5: Non-Binary | H5: Registrations | I5: Completed | J5: Male | K5: Female | L5: Non-Binary | M5: Registrations | N5: Onboarded | O5: Offboarded | P5: Employed | Q5: Donations Received | R5: Re-Donations | S5: Customers Purchased | T5: Total Income | U5: Social Media Outreach | V5: Social Media Engagement | W5: Retail | X5: HR | Y5: Business Supprt | Z5: Marketing | AA5: Stylist | AB5: Clothing Management | AC5: Total | AD5: Retail | AE5: HR | AF5: Business Support | AG5: Marketing | AH5: Stylist | AI5: Clothing Management | AJ5: Total
A6: WEEK 1 | B6: 46083 | C6: 4 | D6: 4 | E6: 1 | F6: 3 | G6: 0 | H6: 3 | I6: 3 | J6: 1 | K6: 1 | L6: 1 | M6: 2 | N6: 0 | O6: 1 | P6: 0 | Q6: 26.5 | R6: 0 | S6: 9 | T6: 251.28 | U6: 465 | V6: 57 | W6: 4 | X6: 1 | Y6: 2 | Z6: 2 | AA6: 4 | AB6: 3 | AC6: =SUM(W6:AB6) -> 16 | AD6: 22 | AE6: 4 | AF6: 5 | AG6: 9 | AH6: 9.5 | AI6: 8.5 | AJ6: =SUM(AD6:AI6) -> 58
B7: 46084 | C7: 4 | D7: 4 | E7: 0 | F7: 4 | G7: 0 | H7: 1 | I7: 1 | J7: 1 | K7: 0 | L7: 0 | M7: 0 | N7: 0 | O7: 0 | P7: 0 | Q7: 19.9 | R7: 16.8 | S7: 19 | T7: 512.57 | U7: 792 | V7: 70 | W7: 3 | X7: 0 | Y7: 1 | Z7: 0 | AA7: 2 | AB7: 3 | AC7: =SUM(W7:AB7) -> 9 | AD7: 13.5 | AE7: 0 | AF7: 3 | AG7: 0 | AH7: 7 | AI7: 14.5 | AJ7: =SUM(AD7:AI7) -> 38
B8: 46085 | C8: 1 | D8: 1 | E8: 0 | F8: 1 | G8: 0 | H8: 3 | I8: 2 | J8: 1 | K8: 1 | L8: 0 | M8: 2 | N8: 0 | O8: 0 | P8: 0 | Q8: 38.2 | R8: 0 | S8: 19 | T8: 492.97 | U8: 1309 | V8: 156 | W8: 4 | X8: 1 | Y8: 2 | Z8: 1 | AA8: 3 | AB8: 1 | AC8: =SUM(W8:AB8) -> 12 | AD8: 16.5 | AE8: 4 | AF8: 9.5 | AG8: 4.5 | AH8: 7.5 | AI8: 2 | AJ8: =SUM(AD8:AI8) -> 44
B9: 46086 | C9: 1 | D9: 1 | E9: 1 | F9: 0 | G9: 0 | H9: 3 | I9: 3 | J9: 1 | K9: 2 | L9: 0 | M9: 0 | N9: 1 | O9: 0 | P9: 0 | Q9: 49.6 | R9: 0 | S9: 7 | T9: 176.01 | U9: 1211 | V9: 172 | W9: 3 | X9: 1 | Y9: 1 | Z9: 1 | AA9: 5 | AB9: 1 | AC9: =SUM(W9:AB9) -> 12 | AD9: 8.5 | AE9: 3 | AF9: 4 | AG9: 2.5 | AH9: 13 | AI9: 2 | AJ9: =SUM(AD9:AI9) -> 33
B10: 46087 | C10: 4 | D10: 3 | E10: 0 | F10: 3 | G10: 0 | H10: 0 | I10: 0 | J10: 0 | K10: 0 | L10: 0 | M10: 1 | N10: 0 | O10: 0 | P10: 0 | Q10: 57.8 | R10: 0 | S10: 12 | T10: 268.84 | U10: 1692 | V10: 93 | W10: 2 | X10: 0 | Y10: 2 | Z10: 1 | AA10: 3 | AB10: 1 | AC10: =SUM(W10:AB10) -> 9 | AD10: 6 | AE10: 0 | AF10: 9.5 | AG10: 4 | AH10: 13.5 | AI10: 5 | AJ10: =SUM(AD10:AI10) -> 38
A11: TOTAL | C11: =SUM(C6:C10) -> 14 | D11: =SUM(D6:D10) -> 13 | E11: =SUM(E6:E10) -> 2 | F11: =SUM(F6:F10) -> 11 | G11: =SUM(G6:G10) -> 0 | H11: =SUM(H6:H10) -> 10 | I11: =SUM(I6:I10) -> 9 | J11: =SUM(J6:J10) -> 4 | ... AJ11: =SUM(AJ6:AJ10) -> 211
A12: WEEK 2 | B12: 46090 | C12: 0 | D12: 0 | E12: 0 | F12: 0 | G12: 0 | H12: 2 | I12: 2 | J12: 1 | K12: 1 | L12: 0 | M12: 1 | N12: 0 | O12: 0 | P12: 0 | Q12: 0 | R12: 3.6 | S12: 6 | T12: 148.02 | U12: 2025 | V12: 284 | W12: 1 | X12: 1 | Y12: 1 | Z12: 1 | AA12: 1 | AB12: 4 | AC12: =SUM(W12:AB12) -> 9 | AD12: 2 | AE12: 5.5 | AF12: 2.5 | AG12: 2 | AH12: 5 | AI12: 12.5 | AJ12: =SUM(AD12:AI12) -> 29.5
B13: 46091 | C13: 3 | D13: 2 | E13: 0 | F13: 2 | G13: 0 | H13: 3 | I13: 2 | J13: 1 | K13: 1 | L13: 0 | M13: 0 | N13: 0 | O13: 0 | P13: 0 | Q13: 38.1 | R13: 0 | S13: 12 | T13: 204.01 | U13: 260 | V13: 16 | W13: 4 | X13: 1 | Y13: 2 | Z13: 1 | AA13: 1 | AB13: 2 | AC13: =SUM(W13:AB13) -> 11 | AD13: 17 | AE13: 2 | AF13: 6.5 | AG13: 4 | AH13: 4 | AI13: 9 | AJ13: =SUM(AD13:AI13) -> 42.5
B14: 46092 | C14: 1 | D14: 0 | E14: 0 | F14: 0 | G14: 0 | H14: 2 | I14: 2 | J14: 1 | K14: 1 | L14: 0 | M14: 2 | N14: 0 | O14: 0 | P14: 0 | Q14: 41.1 | R14: 0 | S14: 11 | T14: 132.74 | U14: 348 | V14: 10 | W14: 1 | X14: 1 | Y14: 1 | Z14: 0 | AA14: 1 | AB14: 1 | AC14: =SUM(W14:AB14) -> 5 | AD14: 4.5 | AE14: 4 | AF14: 3.5 | AG14: 0 | AH14: 5.5 | AI14: 5 | AJ14: =SUM(AD14:AI14) -> 22.5
B15: 46093 | C15: 1 | D15: 1 | E15: 0 | F15: 1 | G15: 0 | H15: 0 | I15: 0 | J15: 0 | K15: 0 | L15: 0 | M15: 1 | N15: 1 | O15: 0 | P15: 0 | Q15: 27.2 | R15: 0 | S15: 10 | T15: 251.42 | U15: 1368 | V15: 191 | W15: 4 | X15: 1 | Y15: 2 | Z15: 1 | AA15: 5 | AB15: 1 | AC15: =SUM(W15:AB15) -> 14 | AD15: 18 | AE15: 4.5 | AF15: 8.5 | AG15: 2 | AH15: 23.5 | AI15: 2.5 | AJ15: =SUM(AD15:AI15) -> 59
B16: 46094 | C16: 0 | D16: 0 | E16: 0 | F16: 0 | G16: 0 | H16: 0 | I16: 0 | J16: 0 | K16: 0 | L16: 0 | M16: 0 | N16: 1 | O16: 0 | P16: 0 | Q16: 28.3 | R16: 0 | S16: 4 | T16: 95.88 | U16: 992 | V16: 115 | W16: 4 | X16: 1 | Y16: 1 | Z16: 2 | AA16: 1 | AB16: 1 | AC16: =SUM(W16:AB16) -> 10 | AD16: 9 | AE16: 4.5 | AF16: 4 | AG16: 11 | AH16: 2.5 | AI16: 4.5 | AJ16: =SUM(AD16:AI16) -> 35.5
A17: TOTAL | C17: =SUM(C12:C16) -> 5 | D17: =SUM(D12:D16) -> 3 | E17: =SUM(E12:E16) -> 0 | F17: =SUM(F12:F16) -> 3 | G17: =SUM(G12:G16) -> 0 | H17: =SUM(H12:H16) -> 7 | I17: =SUM(I12:I16) -> 6 | J17: =SUM(J12:J16) -> 3 | ... AJ17: =SUM(AJ12:AJ16) -> 189
A18: WEEK 3 | B18: 46097 | C18: 0 | D18: 0 | E18: 0 | F18: 0 | G18: 0 | H18: 3 | I18: 3 | J18: 0 | K18: 3 | L18: 0 | M18: 1 | N18: 0 | O18: 0 | P18: 0 | Q18: 44.7 | R18: 0 | S18: 11 | T18: 285.51 | U18: 562 | V18: 71 | W18: 4 | X18: 1 | Y18: 2 | Z18: 1 | AA18: 4 | AB18: 1 | AC18: =SUM(W18:AB18) -> 13 | AD18: 14.5 | AE18: 3.5 | AF18: 10.5 | AG18: 3 | AH18: 8.5 | AI18: 4 | AJ18: =SUM(AD18:AI18) -> 44
